Workbook

Sheet ROTEIRO LUCAS
B1: INDUSTRIA | C1: LOJA | D1: UF | E1: PROMOTORES | F1: SEG | G1: TER | H1: QUA | I1: QUI | J1: SEX | K1: SAB | L1: DOM | M1: VISITAS/SEM (REALIZADO) | N1: FREQ. MENSAL REALIZADA (EST.)
B2: KING | C2: ASSAÍ - GUNTER HANS | D2: MS | E2: ANA LETICIA ORTIZ AVALO | F2: ✓ | M2: =IF(B2="","",COUNTIF(F2:L2,"✓")) -> 1 | N2: =IF(B2="","",IF(M2="","",ROUND(M2*'FREQUÊNCIA INDÚSTRIA'!$B$2,1))) -> 4
B3: KING | C3: COMPER - BRILHANTE | D3: MS | E3: ANA LETICIA ORTIZ AVALO | K3: ✓ | M3: =IF(B3="","",COUNTIF(F3:L3,"✓")) -> 1 | N3: =IF(B3="","",IF(M3="","",ROUND(M3*'FREQUÊNCIA INDÚSTRIA'!$B$2,1))) -> 4
B4: KING | C4: FORT ATACADISTA - ERNESTO GEISEL (COHAFAMA) | D4: MS | E4: ANA LETICIA ORTIZ AVALO | F4: ✓ | I4: ✓ | M4: =IF(B4="","",COUNTIF(F4:L4,"✓")) -> 2 | N4: =IF(B4="","",IF(M4="","",ROUND(M4*'FREQUÊNCIA INDÚSTRIA'!$B$2,1))) -> 8
B5: KING | C5: FORT ATACADISTA - GUANANDI | D5: MS | E5: ANA LETICIA ORTIZ AVALO | I5: ✓ | M5: =IF(B5="","",COUNTIF(F5:L5,"✓")) -> 1 | N5: =IF(B5="","",IF(M5="","",ROUND(M5*'FREQUÊNCIA INDÚSTRIA'!$B$2,1))) -> 4
B6: KING | C6: ATACADÃO - COSTA E SILVA | D6: MS | E6: ANA LETICIA ORTIZ AVALO | M6: =IF(B6="","",COUNTIF(F6:L6,"✓")) -> 0 | N6: =IF(B6="","",IF(M6="","",ROUND(M6*'FREQUÊNCIA INDÚSTRIA'!$B$2,1))) -> 0
B7: APYCE | C7: MAX SUPERMERCADO - SERINGUEIRAS | D7: GO | E7: BRENNO FELIPE GOMES DA SILVA | G7: ✓ | I7: ✓ | M7: =IF(B7="","",COUNTIF(F7:L7,"✓")) -> 2 | N7: =IF(B7="","",IF(M7="","",ROUND(M7*'FREQUÊNCIA INDÚSTRIA'!$B$2,1))) -> 8
B8: APYCE | C8: SUPER LEO | D8: GO | E8: BRENNO FELIPE GOMES DA SILVA | G8: ✓ | I8: ✓ | M8: =IF(B8="","",COUNTIF(F8:L8,"✓")) -> 2 | N8: =IF(B8="","",IF(M8="","",ROUND(M8*'FREQUÊNCIA INDÚSTRIA'!$B$2,1))) -> 8
B9: APYCE | C9: ATACADÃO - GOIAS NORTE 64 (JARDIM GOIÁS) | D9: GO | E9: BRENNO FELIPE GOMES DA SILVA | F9: ✓ | H9: ✓ | J9: ✓ | M9: =IF(B9="","",COUNTIF(F9:L9,"✓")) -> 3 | N9: =IF(B9="","",IF(M9="","",ROUND(M9*'FREQUÊNCIA INDÚSTRIA'!$B$2,1))) -> 12
B10: ALLEZA | C10: ASSAÍ - INDEPENDÊNCIA | D10: GO | E10: BRENNO FELIPE GOMES DA SILVA | J10: ✓ | M10: =IF(B10="","",COUNTIF(F10:L10,"✓")) -> 1 | N10: =IF(B10="","",IF(M10="","",ROUND(M10*'FREQUÊNCIA INDÚSTRIA'!$B$2,1))) -> 4
B11: ALLEZA | C11: ATACADÃO - AV. INDEPENDÊNCIA | D11: GO | E11: BRENNO FELIPE GOMES DA SILVA | F11: ✓ | H11: ✓ | M11: =IF(B11="","",COUNTIF(F11:L11,"✓")) -> 2 | N11: =IF(B11="","",IF(M11="","",ROUND(M11*'FREQUÊNCIA INDÚSTRIA'!$B$2,1))) -> 8
B12: ALLEZA | C12: ATACADÃO - PERIMETRAL | D12: GO | E12: BRENNO FELIPE GOMES DA SILVA | F12: ✓ | H12: ✓ | M12: =IF(B12="","",COUNTIF(F12:L12,"✓")) -> 2 | N12: =IF(B12="","",IF(M12="","",ROUND(M12*'FREQUÊNCIA INDÚSTRIA'!$B$2,1))) -> 8
B13: ALLEZA | C13: ATACADÃO - GOIAS NORTE 64 (JARDIM GOIÁS) | D13: GO | E13: BRENNO FELIPE GOMES DA SILVA | F13: ✓ | H13: ✓ | J13: ✓ | M13: =IF(B13="","",COUNTIF(F13:L13,"✓")) -> 3 | N13: =IF(B13="","",IF(M13="","",ROUND(M13*'FREQUÊNCIA INDÚSTRIA'!$B$2,1))) -> 12
B14: ALLEZA | C14: COSTA ATACADÃO - AV. GOIÁS | D14: GO | E14: BRENNO FELIPE GOMES DA SILVA | F14: ✓ | M14: =IF(B14="","",COUNTIF(F14:L14,"✓")) -> 1 | N14: =IF(B14="","",IF(M14="","",ROUND(M14*'FREQUÊNCIA INDÚSTRIA'!$B$2,1))) -> 4
B15: CO LATICÍNIOS | C15: STORE - PLAZA D'ORO | D15: GO | E15: BRENNO FELIPE GOMES DA SILVA | G15: ✓ | I15: ✓ | K15: ✓ | M15: =IF(B15="","",COUNTIF(F15:L15,"✓")) -> 3 | N15: =IF(B15="","",IF(M15="","",ROUND(M15*'FREQUÊNCIA INDÚSTRIA'!$B$2,1))) -> 12
B16: KING | C16: ATACADÃO - GOIAS NORTE 64 (JARDIM GOIÁS) | D16: GO | E16: BRENNO FELIPE GOMES DA SILVA | F16: ✓ | M16: =IF(B16="","",COUNTIF(F16:L16,"✓")) -> 1 | N16: =IF(B16="","",IF(M16="","",ROUND(M16*'FREQUÊNCIA INDÚSTRIA'!$B$2,1))) -> 4
B17: KING | C17: ATACADÃO - AV. INDEPENDÊNCIA | D17: GO | E17: BRENNO FELIPE GOMES DA SILVA | F17: ✓ | M17: =IF(B17="","",COUNTIF(F17:L17,"✓")) -> 1 | N17: =IF(B17="","",IF(M17="","",ROUND(M17*'FREQUÊNCIA INDÚSTRIA'!$B$2,1))) -> 4
B18: PAMPLONA | C18: ATACADÃO - AV. INDEPENDÊNCIA | D18: GO | E18: BRENNO FELIPE GOMES DA SILVA | F18: ✓ | H18: ✓ | J18: ✓ | M18: =IF(B18="","",COUNTIF(F18:L18,"✓")) -> 3 | N18: =IF(B18="","",IF(M18="","",ROUND(M18*'FREQUÊNCIA INDÚSTRIA'!$B$2,1))) -> 12
B19: PAMPLONA | C19: ATACADÃO - PERIMETRAL | D19: GO | E19: BRENNO FELIPE GOMES DA SILVA | F19: ✓ | H19: ✓ | J19: ✓ | M19: =IF(B19="","",COUNTIF(F19:L19,"✓")) -> 3 | N19: =IF(B19="","",IF(M19="","",ROUND(M19*'FREQUÊNCIA INDÚSTRIA'!$B$2,1))) -> 12
B20: PAMPLONA | C20: ATACADÃO - GOIAS NORTE 64 (JARDIM GOIÁS) | D20: GO | E20: BRENNO FELIPE GOMES DA SILVA | F20: ✓ | H20: ✓ | J20: ✓ | M20: =IF(B20="","",COUNTIF(F20:L20,"✓")) -> 3 | N20: =IF(B20="","",IF(M20="","",ROUND(M20*'FREQUÊNCIA INDÚSTRIA'!$B$2,1))) -> 12
B21: SÃO BRAZ | C21: SUPER LEO | D21: GO | E21: BRENNO FELIPE GOMES DA SILVA | G21: ✓ | M21: =IF(B21="","",COUNTIF(F21:L21,"✓")) -> 1 | N21: =IF(B21="","",IF(M21="","",ROUND(M21*'FREQUÊNCIA INDÚSTRIA'!$B$2,1))) -> 4
B22: SÃO BRAZ | C22: REDE MAX - ELI FORTE | D22: GO | E22: BRENNO FELIPE GOMES DA SILVA | I22: ✓ | M22: =IF(B22="","",COUNTIF(F22:L22,"✓")) -> 1 | N22: =IF(B22="","",IF(M22="","",ROUND(M22*'FREQUÊNCIA INDÚSTRIA'!$B$2,1))) -> 4
B23: SÃO BRAZ | C23: SUPERMERCADO SÃO JOSÉ | D23: GO | E23: BRENNO FELIPE GOMES DA SILVA | K23: ✓ | M23: =IF(B23="","",COUNTIF(F23:L23,"✓")) -> 1 | N23: =IF(B23="","",IF(M23="","",ROUND(M23*'FREQUÊNCIA INDÚSTRIA'!$B$2,1))) -> 4
B24: SÃO BRAZ | C24: REDE MAX-TREMENDAO | D24: GO | E24: BRENNO FELIPE GOMES DA SILVA | I24: ✓ | M24: =IF(B24="","",COUNTIF(F24:L24,"✓")) -> 1 | N24: =IF(B24="","",IF(M24="","",ROUND(M24*'FREQUÊNCIA INDÚSTRIA'!$B$2,1))) -> 4
B25: OXFORD | C25: STORE - PLAZA D'ORO | D25: GO | E25: BRENNO FELIPE GOMES DA SILVA | I25: ✓ | M25: =IF(B25="","",COUNTIF(F25:L25,"✓")) -> 1 | N25: =IF(B25="","",IF(M25="","",ROUND(M25*'FREQUÊNCIA INDÚSTRIA'!$B$2,1))) -> 4
B26: OXFORD | C26: PRO BRAZILIAN - BALNEARIO MEIA PONTE | D26: GO | E26: BRENNO FELIPE GOMES DA SILVA | J26: ✓ | M26: =IF(B26="","",COUNTIF(F26:L26,"✓")) -> 1 | N26: =IF(B26="","",IF(M26="","",ROUND(M26*'FREQUÊNCIA INDÚSTRIA'!$B$2,1))) -> 4
B27: EMBAVI | C27: ASSAÍ - INDEPENDÊNCIA | D27: GO | E27: BRENNO FELIPE GOMES DA SILVA | G27: ✓ | M27: =IF(B27="","",COUNTIF(F27:L27,"✓")) -> 1 | N27: =IF(B27="","",IF(M27="","",ROUND(M27*'FREQUÊNCIA INDÚSTRIA'!$B$2,1))) -> 4
B28: MANTIQUEIRA | C28: COSTA ATACADÃO - SENADOR CANEDO | D28: GO | E28: FABIO CAMARGO DOS SANTOS | I28: ✓ | M28: =IF(B28="","",COUNTIF(F28:L28,"✓")) -> 1 | N28: =IF(B28="","",IF(M28="","",ROUND(M28*'FREQUÊNCIA INDÚSTRIA'!$B$2,1))) -> 4
B29: APYCE | C29: CARREFOUR HIPERMERCADO - GOIANIA SUL JARDINS | D29: GO | E29: FABIO CAMARGO DOS SANTOS | F29: ✓ | M29: =IF(B29="","",COUNTIF(F29:L29,"✓")) -> 1 | N29: =IF(B29="","",IF(M29="","",ROUND(M29*'FREQUÊNCIA INDÚSTRIA'!$B$2,1))) -> 4
B30: ALLEZA | C30: ATACADÃO - GOIANIA FLAMBOYANT 717 | D30: GO | E30: FABIO CAMARGO DOS SANTOS | G30: ✓ | I30: ✓ | K30: ✓ | M30: =IF(B30="","",COUNTIF(F30:L30,"✓")) -> 3 | N30: =IF(B30="","",IF(M30="","",ROUND(M30*'FREQUÊNCIA INDÚSTRIA'!$B$2,1))) -> 12
B31: ALLEZA | C31: ATACADÃO - BR 153 | D31: GO | E31: FABIO CAMARGO DOS SANTOS | F31: ✓ | H31: ✓ | J31: ✓ | M31: =IF(B31="","",COUNTIF(F31:L31,"✓")) -> 3 | N31: =IF(B31="","",IF(M31="","",ROUND(M31*'FREQUÊNCIA INDÚSTRIA'!$B$2,1))) -> 12
B32: ALLEZA | C32: COSTA ATACADÃO - JARDIM GOIAS (Flamboyant) | D32: GO | E32: FABIO CAMARGO DOS SANTOS | J32: ✓ | M32: =IF(B32="","",COUNTIF(F32:L32,"✓")) -> 1 | N32: =IF(B32="","",IF(M32="","",ROUND(M32*'FREQUÊNCIA INDÚSTRIA'!$B$2,1))) -> 4
B33: ALLEZA | C33: COSTA ATACADÃO - SENADOR CANEDO | D33: GO | E33: FABIO CAMARGO DOS SANTOS | I33: ✓ | M33: =IF(B33="","",COUNTIF(F33:L33,"✓")) -> 1 | N33: =IF(B33="","",IF(M33="","",ROUND(M33*'FREQUÊNCIA INDÚSTRIA'!$B$2,1))) -> 4
B34: CO LATICÍNIOS | C34: TATICO CENTRO | D34: GO | E34: FABIO CAMARGO DOS SANTOS | F34: ✓ | G34: ✓ | H34: ✓ | I34: ✓ | J34: ✓ | K34: ✓ | M34: =IF(B34="","",COUNTIF(F34:L34,"✓")) -> 6 | N34: =IF(B34="","",IF(M34="","",ROUND(M34*'FREQUÊNCIA INDÚSTRIA'!$B$2,1))) -> 24
B35: CO LATICÍNIOS | C35: TATICO CAMPINAS | D35: GO | E35: FABIO CAMARGO DOS SANTOS | F35: ✓ | G35: ✓ | H35: ✓ | I35: ✓ | J35: ✓ | K35: ✓ | M35: =IF(B35="","",COUNTIF(F35:L35,"✓")) -> 6 | N35: =IF(B35="","",IF(M35="","",ROUND(M35*'FREQUÊNCIA INDÚSTRIA'!$B$2,1))) -> 24
B36: CO LATICÍNIOS | C36: STORE - VILA MORAIS | D36: GO | E36: FABIO CAMARGO DOS SANTOS | F36: ✓ | G36: ✓ | H36: ✓ | I36: ✓ | J36: ✓ | M36: =IF(B36="","",COUNTIF(F36:L36,"✓")) -> 5 | N36: =IF(B36="","",IF(M36="","",ROUND(M36*'FREQUÊNCIA INDÚSTRIA'!$B$2,1))) -> 20
B37: KING | C37: ATACADÃO - GOIANIA FLAMBOYANT 717 | D37: GO | E37: FABIO CAMARGO DOS SANTOS | G37: ✓ | M37: =IF(B37="","",COUNTIF(F37:L37,"✓")) -> 1 | N37: =IF(B37="","",IF(M37="","",ROUND(M37*'FREQUÊNCIA INDÚSTRIA'!$B$2,1))) -> 4
B38: KING | C38: COSTA ATACADÃO - JARDIM GOIAS (Flamboyant) | D38: GO | E38: FABIO CAMARGO DOS SANTOS | G38: ✓ | M38: =IF(B38="","",COUNTIF(F38:L38,"✓")) -> 1 | N38: =IF(B38="","",IF(M38="","",ROUND(M38*'FREQUÊNCIA INDÚSTRIA'!$B$2,1))) -> 4
B39: PAMPLONA | C39: ATACADÃO - GOIANIA FLAMBOYANT 717 | D39: GO | E39: FABIO CAMARGO DOS SANTOS | I39: ✓ | M39: =IF(B39="","",COUNTIF(F39:L39,"✓")) -> 1 | N39: =IF(B39="","",IF(M39="","",ROUND(M39*'FREQUÊNCIA INDÚSTRIA'!$B$2,1))) -> 4
B40: PAMPLONA | C40: ATACADÃO - BR 153 | D40: GO | E40: FABIO CAMARGO DOS SANTOS | I40: ✓ | M40: =IF(B40="","",COUNTIF(F40:L40,"✓")) -> 1 | N40: =IF(B40="","",IF(M40="","",ROUND(M40*'FREQUÊNCIA INDÚSTRIA'!$B$2,1))) -> 4
...

Sheet CONSULTA LUCAS
B1: Selecione o Promotor: | C1: TOTAL
B2: RODRIGO MARQUES DE OLIVEIRA | C2: =SUMPRODUCT(('ROTEIRO LUCAS'!E2:E499=B2)*('ROTEIRO LUCAS'!F2:L499="✓")) -> 21
B4: INDUSTRIA | C4: LOJA | D4: UF | E4: SEG | F4: TER | G4: QUA | H4: QUI | I4: SEX | J4: SAB | K4: DOM
B5: =IFERROR(__xludf.DUMMYFUNCTION("QUERY('ROTEIRO LUCAS'!B2:L499,""SELECT B,C,D,F,G,H,I,J,K,L WHERE E = '""&B2&""' ORDER BY B"",0)"),"APYCE") -> APYCE | C5: =IFERROR(__xludf.DUMMYFUNCTION("""COMPUTED_VALUE"""),"SUPERVI SUPERMERCADOS JARDIM GOIANO") -> SUPERVI SUPERMERCADOS JARDIM GOIANO | D5: =IFERROR(__xludf.DUMMYFUNCTION("""COMPUTED_VALUE"""),"GO") -> GO | F5: =IFERROR(__xludf.DUMMYFUNCTION("""COMPUTED_VALUE"""),"✓") -> ✓ | H5: =IFERROR(__xludf.DUMMYFUNCTION("""COMPUTED_VALUE"""),"✓") -> ✓
B6: =IFERROR(__xludf.DUMMYFUNCTION("""COMPUTED_VALUE"""),"APYCE") -> APYCE | C6: =IFERROR(__xludf.DUMMYFUNCTION("""COMPUTED_VALUE"""),"SUPERVI SUPERMERCADOS RES DAS FLORES") -> SUPERVI SUPERMERCADOS RES DAS FLORES | D6: =IFERROR(__xludf.DUMMYFUNCTION("""COMPUTED_VALUE"""),"GO") -> GO | H6: =IFERROR(__xludf.DUMMYFUNCTION("""COMPUTED_VALUE"""),"✓") -> ✓ | J6: =IFERROR(__xludf.DUMMYFUNCTION("""COMPUTED_VALUE"""),"✓") -> ✓
B7: =IFERROR(__xludf.DUMMYFUNCTION("""COMPUTED_VALUE"""),"SÃO BRAZ") -> SÃO BRAZ | C7: =IFERROR(__xludf.DUMMYFUNCTION("""COMPUTED_VALUE"""),"SUPERVI SUPERMERCADOS PRESIDENTE KENNEDY") -> SUPERVI SUPERMERCADOS PRESIDENTE KENNEDY | D7: =IFERROR(__xludf.DUMMYFUNCTION("""COMPUTED_VALUE"""),"GO") -> GO | F7: =IFERROR(__xludf.DUMMYFUNCTION("""COMPUTED_VALUE"""),"✓") -> ✓
B8: =IFERROR(__xludf.DUMMYFUNCTION("""COMPUTED_VALUE"""),"SÃO BRAZ") -> SÃO BRAZ | C8: =IFERROR(__xludf.DUMMYFUNCTION("""COMPUTED_VALUE"""),"SUPERMERCADO DO POVO") -> SUPERMERCADO DO POVO | D8: =IFERROR(__xludf.DUMMYFUNCTION("""COMPUTED_VALUE"""),"GO") -> GO | G8: =IFERROR(__xludf.DUMMYFUNCTION("""COMPUTED_VALUE"""),"✓") -> ✓
B9: =IFERROR(__xludf.DUMMYFUNCTION("""COMPUTED_VALUE"""),"SÃO BRAZ") -> SÃO BRAZ | C9: =IFERROR(__xludf.DUMMYFUNCTION("""COMPUTED_VALUE"""),"SUPERVI IAPC") -> SUPERVI IAPC | D9: =IFERROR(__xludf.DUMMYFUNCTION("""COMPUTED_VALUE"""),"GO") -> GO | E9: =IFERROR(__xludf.DUMMYFUNCTION("""COMPUTED_VALUE"""),"✓") -> ✓
B10: =IFERROR(__xludf.DUMMYFUNCTION("""COMPUTED_VALUE"""),"SÃO BRAZ") -> SÃO BRAZ | C10: =IFERROR(__xludf.DUMMYFUNCTION("""COMPUTED_VALUE"""),"SUPERVI BAIRRO JKLOJA 12") -> SUPERVI BAIRRO JKLOJA 12 | D10: =IFERROR(__xludf.DUMMYFUNCTION("""COMPUTED_VALUE"""),"GO") -> GO | J10: =IFERROR(__xludf.DUMMYFUNCTION("""COMPUTED_VALUE"""),"✓") -> ✓
B11: =IFERROR(__xludf.DUMMYFUNCTION("""COMPUTED_VALUE"""),"SÃO BRAZ") -> SÃO BRAZ | C11: =IFERROR(__xludf.DUMMYFUNCTION("""COMPUTED_VALUE"""),"SUPERVI SUPERMERCADOS RES DAS FLORES") -> SUPERVI SUPERMERCADOS RES DAS FLORES | D11: =IFERROR(__xludf.DUMMYFUNCTION("""COMPUTED_VALUE"""),"GO") -> GO | G11: =IFERROR(__xludf.DUMMYFUNCTION("""COMPUTED_VALUE"""),"✓") -> ✓
B12: =IFERROR(__xludf.DUMMYFUNCTION("""COMPUTED_VALUE"""),"SÃO BRAZ") -> SÃO BRAZ | C12: =IFERROR(__xludf.DUMMYFUNCTION("""COMPUTED_VALUE"""),"SUPERMERCADO ALVORADA") -> SUPERMERCADO ALVORADA | D12: =IFERROR(__xludf.DUMMYFUNCTION("""COMPUTED_VALUE"""),"GO") -> GO | H12: =IFERROR(__xludf.DUMMYFUNCTION("""COMPUTED_VALUE"""),"✓") -> ✓
B13: =IFERROR(__xludf.DUMMYFUNCTION("""COMPUTED_VALUE"""),"SÃO BRAZ") -> SÃO BRAZ | C13: =IFERROR(__xludf.DUMMYFUNCTION("""COMPUTED_VALUE"""),"COMERCIAL VILA RICA") -> COMERCIAL VILA RICA | D13: =IFERROR(__xludf.DUMMYFUNCTION("""COMPUTED_VALUE"""),"GO") -> GO | F13: =IFERROR(__xludf.DUMMYFUNCTION("""COMPUTED_VALUE"""),"✓") -> ✓
B14: =IFERROR(__xludf.DUMMYFUNCTION("""COMPUTED_VALUE"""),"SÃO BRAZ") -> SÃO BRAZ | C14: =IFERROR(__xludf.DUMMYFUNCTION("""COMPUTED_VALUE"""),"SUPERMERCADO DO POVO AV PERIMETRAL") -> SUPERMERCADO DO POVO AV PERIMETRAL | D14: =IFERROR(__xludf.DUMMYFUNCTION("""COMPUTED_VALUE"""),"GO") -> GO | E14: =IFERROR(__xludf.DUMMYFUNCTION("""COMPUTED_VALUE"""),"✓") -> ✓
B15: =IFERROR(__xludf.DUMMYFUNCTION("""COMPUTED_VALUE"""),"SÃO BRAZ") -> SÃO BRAZ | C15: =IFERROR(__xludf.DUMMYFUNCTION("""COMPUTED_VALUE"""),"HIPER VIP SUPERMERCADO") -> HIPER VIP SUPERMERCADO | D15: =IFERROR(__xludf.DUMMYFUNCTION("""COMPUTED_VALUE"""),"GO") -> GO | E15: =IFERROR(__xludf.DUMMYFUNCTION("""COMPUTED_VALUE"""),"✓") -> ✓ | I15: =IFERROR(__xludf.DUMMYFUNCTION("""COMPUTED_VALUE"""),"✓") -> ✓
B16: =IFERROR(__xludf.DUMMYFUNCTION("""COMPUTED_VALUE"""),"SÃO BRAZ") -> SÃO BRAZ | C16: =IFERROR(__xludf.DUMMYFUNCTION("""COMPUTED_VALUE"""),"FERREIRA SUPERMERCADO") -> FERREIRA SUPERMERCADO | D16: =IFERROR(__xludf.DUMMYFUNCTION("""COMPUTED_VALUE"""),"GO") -> GO | I16: =IFERROR(__xludf.DUMMYFUNCTION("""COMPUTED_VALUE"""),"✓") -> ✓
B17: =IFERROR(__xludf.DUMMYFUNCTION("""COMPUTED_VALUE"""),"SÃO BRAZ") -> SÃO BRAZ | C17: =IFERROR(__xludf.DUMMYFUNCTION("""COMPUTED_VALUE"""),"SUPERVI RESIDENCIAL DO CERRADO DAIA") -> SUPERVI RESIDENCIAL DO CERRADO DAIA | D17: =IFERROR(__xludf.DUMMYFUNCTION("""COMPUTED_VALUE"""),"GO") -> GO | H17: =IFERROR(__xludf.DUMMYFUNCTION("""COMPUTED_VALUE"""),"✓") -> ✓
B18: =IFERROR(__xludf.DUMMYFUNCTION("""COMPUTED_VALUE"""),"TERMOLAR") -> TERMOLAR | C18: =IFERROR(__xludf.DUMMYFUNCTION("""COMPUTED_VALUE"""),"PEROLA CALIXTOPOLIS") -> PEROLA CALIXTOPOLIS | D18: =IFERROR(__xludf.DUMMYFUNCTION("""COMPUTED_VALUE"""),"GO") -> GO | H18: =IFERROR(__xludf.DUMMYFUNCTION("""COMPUTED_VALUE"""),"✓") -> ✓
B19: =IFERROR(__xludf.DUMMYFUNCTION("""COMPUTED_VALUE"""),"TERMOLAR") -> TERMOLAR | C19: =IFERROR(__xludf.DUMMYFUNCTION("""COMPUTED_VALUE"""),"SUPERVI SUPERMERCADOS JARDIM GOIANO") -> SUPERVI SUPERMERCADOS JARDIM GOIANO | D19: =IFERROR(__xludf.DUMMYFUNCTION("""COMPUTED_VALUE"""),"GO") -> GO | H19: =IFERROR(__xludf.DUMMYFUNCTION("""COMPUTED_VALUE"""),"✓") -> ✓
B20: =IFERROR(__xludf.DUMMYFUNCTION("""COMPUTED_VALUE"""),"TERMOLAR") -> TERMOLAR | C20: =IFERROR(__xludf.DUMMYFUNCTION("""COMPUTED_VALUE"""),"SUPERVI SUPERMERCADOS RES DAS FLORES") -> SUPERVI SUPERMERCADOS RES DAS FLORES | D20: =IFERROR(__xludf.DUMMYFUNCTION("""COMPUTED_VALUE"""),"GO") -> GO | J20: =IFERROR(__xludf.DUMMYFUNCTION("""COMPUTED_VALUE"""),"✓") -> ✓
B21: =IFERROR(__xludf.DUMMYFUNCTION("""COMPUTED_VALUE"""),"TERMOLAR") -> TERMOLAR | C21: =IFERROR(__xludf.DUMMYFUNCTION("""COMPUTED_VALUE"""),"SUPERVI IAPC") -> SUPERVI IAPC | D21: =IFERROR(__xludf.DUMMYFUNCTION("""COMPUTED_VALUE"""),"GO") -> GO | G21: =IFERROR(__xludf.DUMMYFUNCTION("""COMPUTED_VALUE"""),"✓") -> ✓
B22: =IFERROR(__xludf.DUMMYFUNCTION("""COMPUTED_VALUE"""),"TERMOLAR") -> TERMOLAR | C22: =IFERROR(__xludf.DUMMYFUNCTION("""COMPUTED_VALUE"""),"SUPERVI BAIRRO JKLOJA 12") -> SUPERVI BAIRRO JKLOJA 12 | D22: =IFERROR(__xludf.DUMMYFUNCTION("""COMPUTED_VALUE"""),"GO") -> GO | E22: =IFERROR(__xludf.DUMMYFUNCTION("""COMPUTED_VALUE"""),"✓") -> ✓

Sheet ROTEIRO ALEXANDRE
B1: INDUSTRIA | C1: LOJA | D1: UF | E1: PROMOTORES | F1: SEG | G1: TER | H1: QUA | I1: QUI | J1: SEX | K1: SAB | L1: DOM | M1: VISITAS/SEM (REALIZADO) | N1: FREQ. MENSAL REALIZADA (EST.)
B2: AO QUADRADO | C2: DIA A DIA - VICENTE PIRES R 04 | D2: DF | E2: ANDERSON WILLIAMS SANTOS TORRES | K2: ✓ | M2: =IF(B2="","",COUNTIF(F2:L2,"✓")) -> 1 | N2: =IF(B2="","",IF(M2="","",ROUND(M2*'FREQUÊNCIA INDÚSTRIA'!$B$2,1))) -> 4
B3: AO QUADRADO | C3: DIA A DIA - VICENTE PIRES R 12 | D3: DF | E3: ANDERSON WILLIAMS SANTOS TORRES | K3: ✓ | M3: =IF(B3="","",COUNTIF(F3:L3,"✓")) -> 1 | N3: =IF(B3="","",IF(M3="","",ROUND(M3*'FREQUÊNCIA INDÚSTRIA'!$B$2,1))) -> 4
B4: AO QUADRADO | C4: DIA A DIA - VICENTE PIRES R 12 | D4: DF | E4: ANDERSON WILLIAMS SANTOS TORRES | G4: ✓ | M4: =IF(B4="","",COUNTIF(F4:L4,"✓")) -> 1 | N4: =IF(B4="","",IF(M4="","",ROUND(M4*'FREQUÊNCIA INDÚSTRIA'!$B$2,1))) -> 4
B5: AO QUADRADO | C5: DIA A DIA - VICENTE PIRES R 04 | D5: DF | E5: ANDERSON WILLIAMS SANTOS TORRES | G5: ✓ | M5: =IF(B5="","",COUNTIF(F5:L5,"✓")) -> 1 | N5: =IF(B5="","",IF(M5="","",ROUND(M5*'FREQUÊNCIA INDÚSTRIA'!$B$2,1))) -> 4
B6: COPRA | C6: SUPER ADEGA - TAGUATINGA NORTE QNL | D6: DF | E6: ANDERSON WILLIAMS SANTOS TORRES | J6: ✓ | M6: =IF(B6="","",COUNTIF(F6:L6,"✓")) -> 1 | N6: =IF(B6="","",IF(M6="","",ROUND(M6*'FREQUÊNCIA INDÚSTRIA'!$B$2,1))) -> 4
B7: COPRA | C7: SUPER ADEGA - TAGUATINGA NORTE QNL | D7: DF | E7: ANDERSON WILLIAMS SANTOS TORRES | H7: ✓ | M7: =IF(B7="","",COUNTIF(F7:L7,"✓")) -> 1 | N7: =IF(B7="","",IF(M7="","",ROUND(M7*'FREQUÊNCIA INDÚSTRIA'!$B$2,1))) -> 4
B8: KING | C8: COSTA ATACADÃO - TAGUATINGA NORTE | D8: DF | E8: ANDERSON WILLIAMS SANTOS TORRES | I8: ✓ | M8: =IF(B8="","",COUNTIF(F8:L8,"✓")) -> 1 | N8: =IF(B8="","",IF(M8="","",ROUND(M8*'FREQUÊNCIA INDÚSTRIA'!$B$2,1))) -> 4
B9: KING | C9: DIA A DIA - VICENTE PIRES R 12 | D9: DF | E9: ANDERSON WILLIAMS SANTOS TORRES | G9: ✓ | M9: =IF(B9="","",COUNTIF(F9:L9,"✓")) -> 1 | N9: =IF(B9="","",IF(M9="","",ROUND(M9*'FREQUÊNCIA INDÚSTRIA'!$B$2,1))) -> 4
B10: KING | C10: TATICO - VICENTE PIRES RUA 12 | D10: DF | E10: ANDERSON WILLIAMS SANTOS TORRES | F10: ✓ | M10: =IF(B10="","",COUNTIF(F10:L10,"✓")) -> 1 | N10: =IF(B10="","",IF(M10="","",ROUND(M10*'FREQUÊNCIA INDÚSTRIA'!$B$2,1))) -> 4
B11: KING | C11: TATICO - CEILANDIA SUL | D11: DF | E11: ANDERSON WILLIAMS SANTOS TORRES | F11: ✓ | M11: =IF(B11="","",COUNTIF(F11:L11,"✓")) -> 1 | N11: =IF(B11="","",IF(M11="","",ROUND(M11*'FREQUÊNCIA INDÚSTRIA'!$B$2,1))) -> 4
B12: PACHA ALIMENTOS | C12: DIA A DIA - VICENTE PIRES R 04 | D12: DF | E12: ANDERSON WILLIAMS SANTOS TORRES | K12: ✓ | M12: =IF(B12="","",COUNTIF(F12:L12,"✓")) -> 1 | N12: =IF(B12="","",IF(M12="","",ROUND(M12*'FREQUÊNCIA INDÚSTRIA'!$B$2,1))) -> 4
B13: PACHA ALIMENTOS | C13: DIA A DIA - VICENTE PIRES R 12 | D13: DF | E13: ANDERSON WILLIAMS SANTOS TORRES | K13: ✓ | M13: =IF(B13="","",COUNTIF(F13:L13,"✓")) -> 1 | N13: =IF(B13="","",IF(M13="","",ROUND(M13*'FREQUÊNCIA INDÚSTRIA'!$B$2,1))) -> 4
B14: PACHA ALIMENTOS | C14: DIA A DIA - VICENTE PIRES R 12 | D14: DF | E14: ANDERSON WILLIAMS SANTOS TORRES | G14: ✓ | M14: =IF(B14="","",COUNTIF(F14:L14,"✓")) -> 1 | N14: =IF(B14="","",IF(M14="","",ROUND(M14*'FREQUÊNCIA INDÚSTRIA'!$B$2,1))) -> 4
B15: PACHA ALIMENTOS | C15: DIA A DIA - VICENTE PIRES R 04 | D15: DF | E15: ANDERSON WILLIAMS SANTOS TORRES | G15: ✓ | M15: =IF(B15="","",COUNTIF(F15:L15,"✓")) -> 1 | N15: =IF(B15="","",IF(M15="","",ROUND(M15*'FREQUÊNCIA INDÚSTRIA'!$B$2,1))) -> 4
B16: PAMPLONA | C16: SUPER ADEGA - TAGUATINGA NORTE QNL | D16: DF | E16: ANDERSON WILLIAMS SANTOS TORRES | J16: ✓ | M16: =IF(B16="","",COUNTIF(F16:L16,"✓")) -> 1 | N16: =IF(B16="","",IF(M16="","",ROUND(M16*'FREQUÊNCIA INDÚSTRIA'!$B$2,1))) -> 4
B17: PAMPLONA | C17: SUPER ADEGA - TAGUATINGA NORTE QNL | D17: DF | E17: ANDERSON WILLIAMS SANTOS TORRES | H17: ✓ | M17: =IF(B17="","",COUNTIF(F17:L17,"✓")) -> 1 | N17: =IF(B17="","",IF(M17="","",ROUND(M17*'FREQUÊNCIA INDÚSTRIA'!$B$2,1))) -> 4
B18: RB ALIMENTOS | C18: COSTA ATACADÃO - TAGUATINGA NORTE | D18: DF | E18: ANDERSON WILLIAMS SANTOS TORRES | I18: ✓ | M18: =IF(B18="","",COUNTIF(F18:L18,"✓")) -> 1 | N18: =IF(B18="","",IF(M18="","",ROUND(M18*'FREQUÊNCIA INDÚSTRIA'!$B$2,1))) -> 4
B19: RB ALIMENTOS | C19: COSTA ATACADÃO - TAGUATINGA NORTE | D19: DF | E19: ANDERSON WILLIAMS SANTOS TORRES | F19: ✓ | M19: =IF(B19="","",COUNTIF(F19:L19,"✓")) -> 1 | N19: =IF(B19="","",IF(M19="","",ROUND(M19*'FREQUÊNCIA INDÚSTRIA'!$B$2,1))) -> 4
B20: SELETA | C20: SUPER ADEGA - TAGUATINGA NORTE QNL | D20: DF | E20: ANDERSON WILLIAMS SANTOS TORRES | J20: ✓ | M20: =IF(B20="","",COUNTIF(F20:L20,"✓")) -> 1 | N20: =IF(B20="","",IF(M20="","",ROUND(M20*'FREQUÊNCIA INDÚSTRIA'!$B$2,1))) -> 4
B21: SELETA | C21: SUPER ADEGA - TAGUATINGA NORTE QNL | D21: DF | E21: ANDERSON WILLIAMS SANTOS TORRES | H21: ✓ | M21: =IF(B21="","",COUNTIF(F21:L21,"✓")) -> 1 | N21: =IF(B21="","",IF(M21="","",ROUND(M21*'FREQUÊNCIA INDÚSTRIA'!$B$2,1))) -> 4
B22: COOPATOS | C22: DIA A DIA - MESTRE D'ARMAS | D22: DF | E22: ANTONIA AMANDA SIEBRA BATISTA | J22: ✓ | M22: =IF(B22="","",COUNTIF(F22:L22,"✓")) -> 1 | N22: =IF(B22="","",IF(M22="","",ROUND(M22*'FREQUÊNCIA INDÚSTRIA'!$B$2,1))) -> 4
B23: COOPATOS | C23: DIA A DIA - MESTRE D'ARMAS | D23: DF | E23: ANTONIA AMANDA SIEBRA BATISTA | H23: ✓ | M23: =IF(B23="","",COUNTIF(F23:L23,"✓")) -> 1 | N23: =IF(B23="","",IF(M23="","",ROUND(M23*'FREQUÊNCIA INDÚSTRIA'!$B$2,1))) -> 4
B24: COOPATOS | C24: DIA A DIA - MESTRE D'ARMAS | D24: DF | E24: ANTONIA AMANDA SIEBRA BATISTA | F24: ✓ | M24: =IF(B24="","",COUNTIF(F24:L24,"✓")) -> 1 | N24: =IF(B24="","",IF(M24="","",ROUND(M24*'FREQUÊNCIA INDÚSTRIA'!$B$2,1))) -> 4
B25: PACHA ALIMENTOS | C25: DIA A DIA - MESTRE D'ARMAS | D25: DF | E25: ANTONIA AMANDA SIEBRA BATISTA | J25: ✓ | M25: =IF(B25="","",COUNTIF(F25:L25,"✓")) -> 1 | N25: =IF(B25="","",IF(M25="","",ROUND(M25*'FREQUÊNCIA INDÚSTRIA'!$B$2,1))) -> 4
B26: PACHA ALIMENTOS | C26: DIA A DIA - MESTRE D'ARMAS | D26: DF | E26: ANTONIA AMANDA SIEBRA BATISTA | H26: ✓ | M26: =IF(B26="","",COUNTIF(F26:L26,"✓")) -> 1 | N26: =IF(B26="","",IF(M26="","",ROUND(M26*'FREQUÊNCIA INDÚSTRIA'!$B$2,1))) -> 4
B27: PACHA ALIMENTOS | C27: DIA A DIA - MESTRE D'ARMAS | D27: DF | E27: ANTONIA AMANDA SIEBRA BATISTA | F27: ✓ | M27: =IF(B27="","",COUNTIF(F27:L27,"✓")) -> 1 | N27: =IF(B27="","",IF(M27="","",ROUND(M27*'FREQUÊNCIA INDÚSTRIA'!$B$2,1))) -> 4
B28: SELETA | C28: DIA A DIA - MESTRE D'ARMAS | D28: DF | E28: ANTONIA AMANDA SIEBRA BATISTA | J28: ✓ | M28: =IF(B28="","",COUNTIF(F28:L28,"✓")) -> 1 | N28: =IF(B28="","",IF(M28="","",ROUND(M28*'FREQUÊNCIA INDÚSTRIA'!$B$2,1))) -> 4
B29: SELETA | C29: DIA A DIA - MESTRE D'ARMAS | D29: DF | E29: ANTONIA AMANDA SIEBRA BATISTA | H29: ✓ | M29: =IF(B29="","",COUNTIF(F29:L29,"✓")) -> 1 | N29: =IF(B29="","",IF(M29="","",ROUND(M29*'FREQUÊNCIA INDÚSTRIA'!$B$2,1))) -> 4
B30: SELETA | C30: DIA A DIA - MESTRE D'ARMAS | D30: DF | E30: ANTONIA AMANDA SIEBRA BATISTA | F30: ✓ | M30: =IF(B30="","",COUNTIF(F30:L30,"✓")) -> 1 | N30: =IF(B30="","",IF(M30="","",ROUND(M30*'FREQUÊNCIA INDÚSTRIA'!$B$2,1))) -> 4
B31: COOPATOS | C31: DIA A DIA - PLANALTINA DF | D31: DF | E31: ANTONIA AMANDA SIEBRA BATISTA | J31: ✓ | M31: =IF(B31="","",COUNTIF(F31:L31,"✓")) -> 1 | N31: =IF(B31="","",IF(M31="","",ROUND(M31*'FREQUÊNCIA INDÚSTRIA'!$B$2,1))) -> 4
B32: COOPATOS | C32: DIA A DIA - PLANALTINA DF | D32: DF | E32: ANTONIA AMANDA SIEBRA BATISTA | H32: ✓ | M32: =IF(B32="","",COUNTIF(F32:L32,"✓")) -> 1 | N32: =IF(B32="","",IF(M32="","",ROUND(M32*'FREQUÊNCIA INDÚSTRIA'!$B$2,1))) -> 4
B33: COOPATOS | C33: DIA A DIA - PLANALTINA DF | D33: DF | E33: ANTONIA AMANDA SIEBRA BATISTA | F33: ✓ | M33: =IF(B33="","",COUNTIF(F33:L33,"✓")) -> 1 | N33: =IF(B33="","",IF(M33="","",ROUND(M33*'FREQUÊNCIA INDÚSTRIA'!$B$2,1))) -> 4
B34: KING | C34: DIA A DIA - PLANALTINA DF | D34: DF | E34: ANTONIA AMANDA SIEBRA BATISTA | F34: ✓ | M34: =IF(B34="","",COUNTIF(F34:L34,"✓")) -> 1 | N34: =IF(B34="","",IF(M34="","",ROUND(M34*'FREQUÊNCIA INDÚSTRIA'!$B$2,1))) -> 4
B35: PACHA ALIMENTOS | C35: DIA A DIA - PLANALTINA DF | D35: DF | E35: ANTONIA AMANDA SIEBRA BATISTA | J35: ✓ | M35: =IF(B35="","",COUNTIF(F35:L35,"✓")) -> 1 | N35: =IF(B35="","",IF(M35="","",ROUND(M35*'FREQUÊNCIA INDÚSTRIA'!$B$2,1))) -> 4
B36: PACHA ALIMENTOS | C36: DIA A DIA - PLANALTINA DF | D36: DF | E36: ANTONIA AMANDA SIEBRA BATISTA | H36: ✓ | M36: =IF(B36="","",COUNTIF(F36:L36,"✓")) -> 1 | N36: =IF(B36="","",IF(M36="","",ROUND(M36*'FREQUÊNCIA INDÚSTRIA'!$B$2,1))) -> 4
B37: PACHA ALIMENTOS | C37: DIA A DIA - PLANALTINA DF | D37: DF | E37: ANTONIA AMANDA SIEBRA BATISTA | F37: ✓ | M37: =IF(B37="","",COUNTIF(F37:L37,"✓")) -> 1 | N37: =IF(B37="","",IF(M37="","",ROUND(M37*'FREQUÊNCIA INDÚSTRIA'!$B$2,1))) -> 4
B38: SELETA | C38: DIA A DIA - PLANALTINA DF | D38: DF | E38: ANTONIA AMANDA SIEBRA BATISTA | J38: ✓ | M38: =IF(B38="","",COUNTIF(F38:L38,"✓")) -> 1 | N38: =IF(B38="","",IF(M38="","",ROUND(M38*'FREQUÊNCIA INDÚSTRIA'!$B$2,1))) -> 4
B39: SELETA | C39: DIA A DIA - PLANALTINA DF | D39: DF | E39: ANTONIA AMANDA SIEBRA BATISTA | H39: ✓ | M39: =IF(B39="","",COUNTIF(F39:L39,"✓")) -> 1 | N39: =IF(B39="","",IF(M39="","",ROUND(M39*'FREQUÊNCIA INDÚSTRIA'!$B$2,1))) -> 4
B40: SELETA | C40: DIA A DIA - PLANALTINA DF | D40: DF | E40: ANTONIA AMANDA SIEBRA BATISTA | F40: ✓ | M40: =IF(B40="","",COUNTIF(F40:L40,"✓")) -> 1 | N40: =IF(B40="","",IF(M40="","",ROUND(M40*'FREQUÊNCIA INDÚSTRIA'!$B$2,1))) -> 4
...

Sheet CONSULTA ALEXANDRE
B1: Selecione o Promotor: | C1: TOTAL
B2: GÊNESIS PEREIRA SIQUEIRA | C2: =SUMPRODUCT(('ROTEIRO ALEXANDRE'!E2:E503=B2)*('ROTEIRO ALEXANDRE'!F2:L503="✓")) -> 25
B4: INDUSTRIA | C4: LOJA | D4: UF | E4: SEG | F4: TER | G4: QUA | H4: QUI | I4: SEX | J4: SAB | K4: DOM
B5: =IFERROR(__xludf.DUMMYFUNCTION("QUERY('ROTEIRO ALEXANDRE'!B2:L503,""SELECT B,C,D,F,G,H,I,J,K,L WHERE E = '""&B2&""' ORDER BY B"",0)"),"ALLEZA") -> ALLEZA | C5: =IFERROR(__xludf.DUMMYFUNCTION("""COMPUTED_VALUE"""),"ASSAÍ - BRASÍLIA SIA") -> ASSAÍ - BRASÍLIA SIA | D5: =IFERROR(__xludf.DUMMYFUNCTION("""COMPUTED_VALUE"""),"DF") -> DF | F5: =IFERROR(__xludf.DUMMYFUNCTION("""COMPUTED_VALUE"""),"✓") -> ✓
B6: =IFERROR(__xludf.DUMMYFUNCTION("""COMPUTED_VALUE"""),"ALLEZA") -> ALLEZA | C6: =IFERROR(__xludf.DUMMYFUNCTION("""COMPUTED_VALUE"""),"ASSAÍ - BRASÍLIA SIA") -> ASSAÍ - BRASÍLIA SIA | D6: =IFERROR(__xludf.DUMMYFUNCTION("""COMPUTED_VALUE"""),"DF") -> DF | H6: =IFERROR(__xludf.DUMMYFUNCTION("""COMPUTED_VALUE"""),"✓") -> ✓
B7: =IFERROR(__xludf.DUMMYFUNCTION("""COMPUTED_VALUE"""),"AO QUADRADO") -> AO QUADRADO | C7: =IFERROR(__xludf.DUMMYFUNCTION("""COMPUTED_VALUE"""),"DIA A DIA - SIA") -> DIA A DIA - SIA | D7: =IFERROR(__xludf.DUMMYFUNCTION("""COMPUTED_VALUE"""),"DF") -> DF | F7: =IFERROR(__xludf.DUMMYFUNCTION("""COMPUTED_VALUE"""),"✓") -> ✓
B8: =IFERROR(__xludf.DUMMYFUNCTION("""COMPUTED_VALUE"""),"AO QUADRADO") -> AO QUADRADO | C8: =IFERROR(__xludf.DUMMYFUNCTION("""COMPUTED_VALUE"""),"DIA A DIA - SIA") -> DIA A DIA - SIA | D8: =IFERROR(__xludf.DUMMYFUNCTION("""COMPUTED_VALUE"""),"DF") -> DF | H8: =IFERROR(__xludf.DUMMYFUNCTION("""COMPUTED_VALUE"""),"✓") -> ✓
B9: =IFERROR(__xludf.DUMMYFUNCTION("""COMPUTED_VALUE"""),"COPRA") -> COPRA | C9: =IFERROR(__xludf.DUMMYFUNCTION("""COMPUTED_VALUE"""),"SUPER ADEGA - SIA") -> SUPER ADEGA - SIA | D9: =IFERROR(__xludf.DUMMYFUNCTION("""COMPUTED_VALUE"""),"DF") -> DF | E9: =IFERROR(__xludf.DUMMYFUNCTION("""COMPUTED_VALUE"""),"✓") -> ✓
B10: =IFERROR(__xludf.DUMMYFUNCTION("""COMPUTED_VALUE"""),"COPRA") -> COPRA | C10: =IFERROR(__xludf.DUMMYFUNCTION("""COMPUTED_VALUE"""),"SUPER ADEGA - SIA") -> SUPER ADEGA - SIA | D10: =IFERROR(__xludf.DUMMYFUNCTION("""COMPUTED_VALUE"""),"DF") -> DF | G10: =IFERROR(__xludf.DUMMYFUNCTION("""COMPUTED_VALUE"""),"✓") -> ✓
B11: =IFERROR(__xludf.DUMMYFUNCTION("""COMPUTED_VALUE"""),"COPRA") -> COPRA | C11: =IFERROR(__xludf.DUMMYFUNCTION("""COMPUTED_VALUE"""),"SUPER ADEGA - SIA") -> SUPER ADEGA - SIA | D11: =IFERROR(__xludf.DUMMYFUNCTION("""COMPUTED_VALUE"""),"DF") -> DF | I11: =IFERROR(__xludf.DUMMYFUNCTION("""COMPUTED_VALUE"""),"✓") -> ✓
B12: =IFERROR(__xludf.DUMMYFUNCTION("""COMPUTED_VALUE"""),"DON LUIZ") -> DON LUIZ | C12: =IFERROR(__xludf.DUMMYFUNCTION("""COMPUTED_VALUE"""),"ATACADÃO - BRASÍLIA SIA") -> ATACADÃO - BRASÍLIA SIA | D12: =IFERROR(__xludf.DUMMYFUNCTION("""COMPUTED_VALUE"""),"DF") -> DF | E12: =IFERROR(__xludf.DUMMYFUNCTION("""COMPUTED_VALUE"""),"✓") -> ✓
B13: =IFERROR(__xludf.DUMMYFUNCTION("""COMPUTED_VALUE"""),"EMBAVI") -> EMBAVI | C13: =IFERROR(__xludf.DUMMYFUNCTION("""COMPUTED_VALUE"""),"ASSAÍ - BRASÍLIA SIA") -> ASSAÍ - BRASÍLIA SIA | D13: =IFERROR(__xludf.DUMMYFUNCTION("""COMPUTED_VALUE"""),"DF") -> DF | F13: =IFERROR(__xludf.DUMMYFUNCTION("""COMPUTED_VALUE"""),"✓") -> ✓
B14: =IFERROR(__xludf.DUMMYFUNCTION("""COMPUTED_VALUE"""),"EMBAVI") -> EMBAVI | C14: =IFERROR(__xludf.DUMMYFUNCTION("""COMPUTED_VALUE"""),"ASSAÍ - BRASÍLIA SIA") -> ASSAÍ - BRASÍLIA SIA | D14: =IFERROR(__xludf.DUMMYFUNCTION("""COMPUTED_VALUE"""),"DF") -> DF | H14: =IFERROR(__xludf.DUMMYFUNCTION("""COMPUTED_VALUE"""),"✓") -> ✓
B15: =IFERROR(__xludf.DUMMYFUNCTION("""COMPUTED_VALUE"""),"EMBAVI") -> EMBAVI | C15: =IFERROR(__xludf.DUMMYFUNCTION("""COMPUTED_VALUE"""),"ASSAÍ - BRASÍLIA SIA") -> ASSAÍ - BRASÍLIA SIA | D15: =IFERROR(__xludf.DUMMYFUNCTION("""COMPUTED_VALUE"""),"DF") -> DF | J15: =IFERROR(__xludf.DUMMYFUNCTION("""COMPUTED_VALUE"""),"✓") -> ✓
B16: =IFERROR(__xludf.DUMMYFUNCTION("""COMPUTED_VALUE"""),"KING") -> KING | C16: =IFERROR(__xludf.DUMMYFUNCTION("""COMPUTED_VALUE"""),"ATACADÃO - BRASÍLIA SIA") -> ATACADÃO - BRASÍLIA SIA | D16: =IFERROR(__xludf.DUMMYFUNCTION("""COMPUTED_VALUE"""),"DF") -> DF | E16: =IFERROR(__xludf.DUMMYFUNCTION("""COMPUTED_VALUE"""),"✓") -> ✓
B17: =IFERROR(__xludf.DUMMYFUNCTION("""COMPUTED_VALUE"""),"KING") -> KING | C17: =IFERROR(__xludf.DUMMYFUNCTION("""COMPUTED_VALUE"""),"SUPER ADEGA - SIA") -> SUPER ADEGA - SIA | D17: =IFERROR(__xludf.DUMMYFUNCTION("""COMPUTED_VALUE"""),"DF") -> DF | E17: =IFERROR(__xludf.DUMMYFUNCTION("""COMPUTED_VALUE"""),"✓") -> ✓
B18: =IFERROR(__xludf.DUMMYFUNCTION("""COMPUTED_VALUE"""),"KING") -> KING | C18: =IFERROR(__xludf.DUMMYFUNCTION("""COMPUTED_VALUE"""),"ASSAÍ - BRASÍLIA SIA") -> ASSAÍ - BRASÍLIA SIA | D18: =IFERROR(__xludf.DUMMYFUNCTION("""COMPUTED_VALUE"""),"DF") -> DF | F18: =IFERROR(__xludf.DUMMYFUNCTION("""COMPUTED_VALUE"""),"✓") -> ✓
B19: =IFERROR(__xludf.DUMMYFUNCTION("""COMPUTED_VALUE"""),"PACHA ALIMENTOS") -> PACHA ALIMENTOS | C19: =IFERROR(__xludf.DUMMYFUNCTION("""COMPUTED_VALUE"""),"DIA A DIA - SIA") -> DIA A DIA - SIA | D19: =IFERROR(__xludf.DUMMYFUNCTION("""COMPUTED_VALUE"""),"DF") -> DF | F19: =IFERROR(__xludf.DUMMYFUNCTION("""COMPUTED_VALUE"""),"✓") -> ✓
B20: =IFERROR(__xludf.DUMMYFUNCTION("""COMPUTED_VALUE"""),"PACHA ALIMENTOS") -> PACHA ALIMENTOS | C20: =IFERROR(__xludf.DUMMYFUNCTION("""COMPUTED_VALUE"""),"DIA A DIA - SIA") -> DIA A DIA - SIA | D20: =IFERROR(__xludf.DUMMYFUNCTION("""COMPUTED_VALUE"""),"DF") -> DF | H20: =IFERROR(__xludf.DUMMYFUNCTION("""COMPUTED_VALUE"""),"✓") -> ✓
B21: =IFERROR(__xludf.DUMMYFUNCTION("""COMPUTED_VALUE"""),"PAMPLONA") -> PAMPLONA | C21: =IFERROR(__xludf.DUMMYFUNCTION("""COMPUTED_VALUE"""),"ATACADÃO - BRASÍLIA SIA") -> ATACADÃO - BRASÍLIA SIA | D21: =IFERROR(__xludf.DUMMYFUNCTION("""COMPUTED_VALUE"""),"DF") -> DF | E21: =IFERROR(__xludf.DUMMYFUNCTION("""COMPUTED_VALUE"""),"✓") -> ✓
B22: =IFERROR(__xludf.DUMMYFUNCTION("""COMPUTED_VALUE"""),"PAMPLONA") -> PAMPLONA | C22: =IFERROR(__xludf.DUMMYFUNCTION("""COMPUTED_VALUE"""),"SUPER ADEGA - SIA") -> SUPER ADEGA - SIA | D22: =IFERROR(__xludf.DUMMYFUNCTION("""COMPUTED_VALUE"""),"DF") -> DF | E22: =IFERROR(__xludf.DUMMYFUNCTION("""COMPUTED_VALUE"""),"✓") -> ✓
B23: =IFERROR(__xludf.DUMMYFUNCTION("""COMPUTED_VALUE"""),"PAMPLONA") -> PAMPLONA | C23: =IFERROR(__xludf.DUMMYFUNCTION("""COMPUTED_VALUE"""),"ATACADÃO - BRASÍLIA SIA") -> ATACADÃO - BRASÍLIA SIA | D23: =IFERROR(__xludf.DUMMYFUNCTION("""COMPUTED_VALUE"""),"DF") -> DF | G23: =IFERROR(__xludf.DUMMYFUNCTION("""COMPUTED_VALUE"""),"✓") -> ✓
B24: =IFERROR(__xludf.DUMMYFUNCTION("""COMPUTED_VALUE"""),"PAMPLONA") -> PAMPLONA | C24: =IFERROR(__xludf.DUMMYFUNCTION("""COMPUTED_VALUE"""),"SUPER ADEGA - SIA") -> SUPER ADEGA - SIA | D24: =IFERROR(__xludf.DUMMYFUNCTION("""COMPUTED_VALUE"""),"DF") -> DF | G24: =IFERROR(__xludf.DUMMYFUNCTION("""COMPUTED_VALUE"""),"✓") -> ✓
B25: =IFERROR(__xludf.DUMMYFUNCTION("""COMPUTED_VALUE"""),"PAMPLONA") -> PAMPLONA | C25: =IFERROR(__xludf.DUMMYFUNCTION("""COMPUTED_VALUE"""),"ATACADÃO - BRASÍLIA SIA") -> ATACADÃO - BRASÍLIA SIA | D25: =IFERROR(__xludf.DUMMYFUNCTION("""COMPUTED_VALUE"""),"DF") -> DF | I25: =IFERROR(__xludf.DUMMYFUNCTION("""COMPUTED_VALUE"""),"✓") -> ✓
B26: =IFERROR(__xludf.DUMMYFUNCTION("""COMPUTED_VALUE"""),"PAMPLONA") -> PAMPLONA | C26: =IFERROR(__xludf.DUMMYFUNCTION("""COMPUTED_VALUE"""),"SUPER ADEGA - SIA") -> SUPER ADEGA - SIA | D26: =IFERROR(__xludf.DUMMYFUNCTION("""COMPUTED_VALUE"""),"DF") -> DF | I26: =IFERROR(__xludf.DUMMYFUNCTION("""COMPUTED_VALUE"""),"✓") -> ✓
B27: =IFERROR(__xludf.DUMMYFUNCTION("""COMPUTED_VALUE"""),"SELETA") -> SELETA | C27: =IFERROR(__xludf.DUMMYFUNCTION("""COMPUTED_VALUE"""),"SUPER ADEGA - SIA") -> SUPER ADEGA - SIA | D27: =IFERROR(__xludf.DUMMYFUNCTION("""COMPUTED_VALUE"""),"DF") -> DF | E27: =IFERROR(__xludf.DUMMYFUNCTION("""COMPUTED_VALUE"""),"✓") -> ✓
B28: =IFERROR(__xludf.DUMMYFUNCTION("""COMPUTED_VALUE"""),"SELETA") -> SELETA | C28: =IFERROR(__xludf.DUMMYFUNCTION("""COMPUTED_VALUE"""),"SUPER ADEGA - SIA") -> SUPER ADEGA - SIA | D28: =IFERROR(__xludf.DUMMYFUNCTION("""COMPUTED_VALUE"""),"DF") -> DF | G28: =IFERROR(__xludf.DUMMYFUNCTION("""COMPUTED_VALUE"""),"✓") -> ✓
B29: =IFERROR(__xludf.DUMMYFUNCTION("""COMPUTED_VALUE"""),"SELETA") -> SELETA | C29: =IFERROR(__xludf.DUMMYFUNCTION("""COMPUTED_VALUE"""),"DIA A DIA - SIA") -> DIA A DIA - SIA | D29: =IFERROR(__xludf.DUMMYFUNCTION("""COMPUTED_VALUE"""),"DF") -> DF | J29: =IFERROR(__xludf.DUMMYFUNCTION("""COMPUTED_VALUE"""),"✓") -> ✓

Sheet FREQUÊNCIA INDÚSTRIA
B1: Semanas por mês (para converter check semanal em frequência mensal):
B2: 4
B6: INDÚSTRIA | C6: FREQ. MENSAL CONTRATADA (TOTAL) | D6: FREQ. MENSAL REALIZADA (TOTAL EST.) | E6: DIFERENÇA | F6: STATUS
B7: =INDUSTRIA!A2 -> ALLEZA | C7: 144 | D7: =SUMIF('ROTEIRO LUCAS'!$B$2:$B$299,$B7,'ROTEIRO LUCAS'!$N$2:$N$299)+SUMIF('ROTEIRO ALEXANDRE'!$B$2:$B$320,$B7,'ROTEIRO ALEXANDRE'!$N$2:$N$320) -> 188 | E7: =D7-C7 -> 44 | F7: =IF(C7=0,"SEM META",IF(D7>=C7,"OK","ABAIXO DO CONTRATADO")) -> OK
B8: =INDUSTRIA!A3 -> AUTENTICOCO | C8: 192 | D8: =SUMIF('ROTEIRO LUCAS'!$B$2:$B$299,$B8,'ROTEIRO LUCAS'!$N$2:$N$299)+SUMIF('ROTEIRO ALEXANDRE'!$B$2:$B$320,$B8,'ROTEIRO ALEXANDRE'!$N$2:$N$320) -> 16 | E8: =D8-C8 -> -176 | F8: =IF(C8=0,"SEM META",IF(D8>=C8,"OK","ABAIXO DO CONTRATADO")) -> ABAIXO DO CONTRATADO
B9: =INDUSTRIA!A4 -> AO QUADRADO | C9: 50 | D9: =SUMIF('ROTEIRO LUCAS'!$B$2:$B$299,$B9,'ROTEIRO LUCAS'!$N$2:$N$299)+SUMIF('ROTEIRO ALEXANDRE'!$B$2:$B$320,$B9,'ROTEIRO ALEXANDRE'!$N$2:$N$320) -> 72 | E9: =D9-C9 -> 22 | F9: =IF(C9=0,"SEM META",IF(D9>=C9,"OK","ABAIXO DO CONTRATADO")) -> OK
B10: =INDUSTRIA!A5 -> COPRA | C10: 84 | D10: =SUMIF('ROTEIRO LUCAS'!$B$2:$B$299,$B10,'ROTEIRO LUCAS'!$N$2:$N$299)+SUMIF('ROTEIRO ALEXANDRE'!$B$2:$B$320,$B10,'ROTEIRO ALEXANDRE'!$N$2:$N$320) -> 56 | E10: =D10-C10 -> -28 | F10: =IF(C10=0,"SEM META",IF(D10>=C10,"OK","ABAIXO DO CONTRATADO")) -> ABAIXO DO CONTRATADO
B11: =INDUSTRIA!A6 -> CICOPAL GO | C11: 79 | D11: =SUMIF('ROTEIRO LUCAS'!$B$2:$B$299,$B11,'ROTEIRO LUCAS'!$N$2:$N$299)+SUMIF('ROTEIRO ALEXANDRE'!$B$2:$B$320,$B11,'ROTEIRO ALEXANDRE'!$N$2:$N$320) -> 0 | E11: =D11-C11 -> -79 | F11: =IF(C11=0,"SEM META",IF(D11>=C11,"OK","ABAIXO DO CONTRATADO")) -> ABAIXO DO CONTRATADO
B12: =INDUSTRIA!A7 -> CO LATICÍNIOS | C12: 252 | D12: =SUMIF('ROTEIRO LUCAS'!$B$2:$B$299,$B12,'ROTEIRO LUCAS'!$N$2:$N$299)+SUMIF('ROTEIRO ALEXANDRE'!$B$2:$B$320,$B12,'ROTEIRO ALEXANDRE'!$N$2:$N$320) -> 168 | E12: =D12-C12 -> -84 | F12: =IF(C12=0,"SEM META",IF(D12>=C12,"OK","ABAIXO DO CONTRATADO")) -> ABAIXO DO CONTRATADO
B13: =INDUSTRIA!A8 -> COOPATOS | C13: 72 | D13: =SUMIF('ROTEIRO LUCAS'!$B$2:$B$299,$B13,'ROTEIRO LUCAS'!$N$2:$N$299)+SUMIF('ROTEIRO ALEXANDRE'!$B$2:$B$320,$B13,'ROTEIRO ALEXANDRE'!$N$2:$N$320) -> 48 | E13: =D13-C13 -> -24 | F13: =IF(C13=0,"SEM META",IF(D13>=C13,"OK","ABAIXO DO CONTRATADO")) -> ABAIXO DO CONTRATADO
B14: =INDUSTRIA!A9 -> FRUTA POLPA | C14: 24 | D14: =SUMIF('ROTEIRO LUCAS'!$B$2:$B$299,$B14,'ROTEIRO LUCAS'!$N$2:$N$299)+SUMIF('ROTEIRO ALEXANDRE'!$B$2:$B$320,$B14,'ROTEIRO ALEXANDRE'!$N$2:$N$320) -> 0 | E14: =D14-C14 -> -24 | F14: =IF(C14=0,"SEM META",IF(D14>=C14,"OK","ABAIXO DO CONTRATADO")) -> ABAIXO DO CONTRATADO
B15: =INDUSTRIA!A10 -> GRUPO AMA | F15: =IF(C15=0,"SEM META",IF(D15>=C15,"OK","ABAIXO DO CONTRATADO")) -> SEM META
B16: =INDUSTRIA!A11 -> DON LUIZ | C16: 32 | D16: =SUMIF('ROTEIRO LUCAS'!$B$2:$B$299,$B16,'ROTEIRO LUCAS'!$N$2:$N$299)+SUMIF('ROTEIRO ALEXANDRE'!$B$2:$B$320,$B16,'ROTEIRO ALEXANDRE'!$N$2:$N$320) -> 20 | E16: =D16-C16 -> -12 | F16: =IF(C16=0,"SEM META",IF(D16>=C16,"OK","ABAIXO DO CONTRATADO")) -> ABAIXO DO CONTRATADO
B17: =INDUSTRIA!A12 -> RB ALIMENTOS | C17: 58 | D17: =SUMIF('ROTEIRO LUCAS'!$B$2:$B$299,$B17,'ROTEIRO LUCAS'!$N$2:$N$299)+SUMIF('ROTEIRO ALEXANDRE'!$B$2:$B$320,$B17,'ROTEIRO ALEXANDRE'!$N$2:$N$320) -> 76 | E17: =D17-C17 -> 18 | F17: =IF(C17=0,"SEM META",IF(D17>=C17,"OK","ABAIXO DO CONTRATADO")) -> OK
B18: =INDUSTRIA!A13 -> KING | C18: 530 | D18: =SUMIF('ROTEIRO LUCAS'!$B$2:$B$299,$B18,'ROTEIRO LUCAS'!$N$2:$N$299)+SUMIF('ROTEIRO ALEXANDRE'!$B$2:$B$320,$B18,'ROTEIRO ALEXANDRE'!$N$2:$N$320) -> 264 | E18: =D18-C18 -> -266 | F18: =IF(C18=0,"SEM META",IF(D18>=C18,"OK","ABAIXO DO CONTRATADO")) -> ABAIXO DO CONTRATADO
B19: =INDUSTRIA!A14 -> MANTIQUEIRA | C19: 28 | D19: =SUMIF('ROTEIRO LUCAS'!$B$2:$B$299,$B19,'ROTEIRO LUCAS'!$N$2:$N$299)+SUMIF('ROTEIRO ALEXANDRE'!$B$2:$B$320,$B19,'ROTEIRO ALEXANDRE'!$N$2:$N$320) -> 28 | E19: =D19-C19 -> 0 | F19: =IF(C19=0,"SEM META",IF(D19>=C19,"OK","ABAIXO DO CONTRATADO")) -> OK
B20: =INDUSTRIA!A15 -> MEDFIO | C20: 36 | D20: =SUMIF('ROTEIRO LUCAS'!$B$2:$B$299,$B20,'ROTEIRO LUCAS'!$N$2:$N$299)+SUMIF('ROTEIRO ALEXANDRE'!$B$2:$B$320,$B20,'ROTEIRO ALEXANDRE'!$N$2:$N$320) -> 0 | E20: =D20-C20 -> -36 | F20: =IF(C20=0,"SEM META",IF(D20>=C20,"OK","ABAIXO DO CONTRATADO")) -> ABAIXO DO CONTRATADO
B21: =INDUSTRIA!A16 -> MENDEZ | C21: 40 | D21: =SUMIF('ROTEIRO LUCAS'!$B$2:$B$299,$B21,'ROTEIRO LUCAS'!$N$2:$N$299)+SUMIF('ROTEIRO ALEXANDRE'!$B$2:$B$320,$B21,'ROTEIRO ALEXANDRE'!$N$2:$N$320) -> 4 | E21: =D21-C21 -> -36 | F21: =IF(C21=0,"SEM META",IF(D21>=C21,"OK","ABAIXO DO CONTRATADO")) -> ABAIXO DO CONTRATADO
B22: =INDUSTRIA!A17 -> MISSIATO | C22: 64 | D22: =SUMIF('ROTEIRO LUCAS'!$B$2:$B$299,$B22,'ROTEIRO LUCAS'!$N$2:$N$299)+SUMIF('ROTEIRO ALEXANDRE'!$B$2:$B$320,$B22,'ROTEIRO ALEXANDRE'!$N$2:$N$320) -> 12 | E22: =D22-C22 -> -52 | F22: =IF(C22=0,"SEM META",IF(D22>=C22,"OK","ABAIXO DO CONTRATADO")) -> ABAIXO DO CONTRATADO
B23: =INDUSTRIA!A18 -> PAMPLONA | C23: 372 | D23: =SUMIF('ROTEIRO LUCAS'!$B$2:$B$299,$B23,'ROTEIRO LUCAS'!$N$2:$N$299)+SUMIF('ROTEIRO ALEXANDRE'!$B$2:$B$320,$B23,'ROTEIRO ALEXANDRE'!$N$2:$N$320) -> 252 | E23: =D23-C23 -> -120 | F23: =IF(C23=0,"SEM META",IF(D23>=C23,"OK","ABAIXO DO CONTRATADO")) -> ABAIXO DO CONTRATADO
B24: =INDUSTRIA!A19 -> PACHA ALIMENTOS | C24: 348 | D24: =SUMIF('ROTEIRO LUCAS'!$B$2:$B$299,$B24,'ROTEIRO LUCAS'!$N$2:$N$299)+SUMIF('ROTEIRO ALEXANDRE'!$B$2:$B$320,$B24,'ROTEIRO ALEXANDRE'!$N$2:$N$320) -> 156 | E24: =D24-C24 -> -192 | F24: =IF(C24=0,"SEM META",IF(D24>=C24,"OK","ABAIXO DO CONTRATADO")) -> ABAIXO DO CONTRATADO
B25: =INDUSTRIA!A20 -> PIRACANJUBA | C25: 16 | D25: =SUMIF('ROTEIRO LUCAS'!$B$2:$B$299,$B25,'ROTEIRO LUCAS'!$N$2:$N$299)+SUMIF('ROTEIRO ALEXANDRE'!$B$2:$B$320,$B25,'ROTEIRO ALEXANDRE'!$N$2:$N$320) -> 0 | E25: =D25-C25 -> -16 | F25: =IF(C25=0,"SEM META",IF(D25>=C25,"OK","ABAIXO DO CONTRATADO")) -> ABAIXO DO CONTRATADO
B26: =INDUSTRIA!A21 -> SÃO BRAZ | C26: 168 | D26: =SUMIF('ROTEIRO LUCAS'!$B$2:$B$299,$B26,'ROTEIRO LUCAS'!$N$2:$N$299)+SUMIF('ROTEIRO ALEXANDRE'!$B$2:$B$320,$B26,'ROTEIRO ALEXANDRE'!$N$2:$N$320) -> 132 | E26: =D26-C26 -> -36 | F26: =IF(C26=0,"SEM META",IF(D26>=C26,"OK","ABAIXO DO CONTRATADO")) -> ABAIXO DO CONTRATADO
B27: =INDUSTRIA!A22 -> SELETA | C27: 76 | D27: =SUMIF('ROTEIRO LUCAS'!$B$2:$B$299,$B27,'ROTEIRO LUCAS'!$N$2:$N$299)+SUMIF('ROTEIRO ALEXANDRE'!$B$2:$B$320,$B27,'ROTEIRO ALEXANDRE'!$N$2:$N$320) -> 148 | E27: =D27-C27 -> 72 | F27: =IF(C27=0,"SEM META",IF(D27>=C27,"OK","ABAIXO DO CONTRATADO")) -> OK
... B31: =INDUSTRIA!A26 -> APYCE | C31: 100 | D31: =SUMIF('ROTEIRO LUCAS'!$B$2:$B$299,$B31,'ROTEIRO LUCAS'!$N$2:$N$299)+SUMIF('ROTEIRO ALEXANDRE'!$B$2:$B$320,$B31,'ROTEIRO ALEXANDRE'!$N$2:$N$320) -> 116 | E31: =D31-C31 -> 16 | F31: =IF(C31=0,"SEM META",IF(D31>=C31,"OK","ABAIXO DO CONTRATADO")) -> OK
B32: =INDUSTRIA!A27 -> CHULETÃO
B33: =INDUSTRIA!A28
B34: =INDUSTRIA!A28
B35: =INDUSTRIA!A29
B36: =INDUSTRIA!A29
B37: =INDUSTRIA!A30

Sheet PROMOTORES
A1: ID | B1: NOME | C1: CIDADE ATENDIMENTO | D1: CONTATO | E1: Loja | F1: Observação
A2: 39 | B2: ALEXANDRE FREITAS DA SILVA | D2: =+556183110460 -> 556183110460
A3: 37 | B3: JHONATTA WISNNER GONÇALVES | D3: =+556182177307 -> 556182177307
A4: 65 | B4: ANDERSON WILLIAMS SANTOS TORRES | C4: PISTÃO SUL | D4: =+556198011855 -> 556198011855
A5: 1 | B5: CARLOS DA GUIA NUNES | C5: GAMA E NOVO GAMA | D5: =+556193828554 -> 556193828554
A6: 54 | B6: PAULO VICTOR RODRIGUES DE ALMEIDA | C6: SOBRADINHO | D6: =+556195847193 -> 556195847193
A7: 2 | B7: ANTONIA AMANDA SIEBRA BATISTA | C7: PLANALTINA GOIAS E DF | D7: =+556193123343 -> 556193123343
A8: 8 | B8: GRAZIELE MELO SILVA ALVES | C8: CEILANDIA E AGUAS CLARAS | D8: =+556181054165 -> 556181054165
A9: 3 | B9: FRANCISCO PEREIRA MASCIMO | C9: AGUAS LINDAS / 070 | D9: =+556195182536 -> 556195182536
A10: 4 | B10: SAMILLE APARECIDA DOS SANTOS DAMASCENO BARBOSA | C10: EPTG / AGUAS / GUARA | D10: =+556193394605 -> 556193394605
A11: 45 | B11: MARIA EDUARDA CARDOSO DOS SANTOS | D11: =+556182529308 -> 556182529308
A12: 12 | B12: GUILHERME RODRIGUES SILVA DE LIMA | C12: VICENTE PIRES / TATICO DA CEILANDIA / TAGUATINGA | D12: =+556181980238 -> 556181980238
A13: 7 | B13: FRANKLIN MATOS RODRIGUES | C13: VALPARAISO / LUZIANIA | D13: =+556191008170 -> 556191008170
A14: 44 | B14: PRISCYLLA GOMES DA SILVA | C14: SAMAMBAIA/ RIACHO / RECANTO | D14: =+556196290083 -> 556196290083
A15: 38 | B15: LUCAS MATHEUS MOREIRA SILVA | C15: GOIANIA | D15: =+556292627000 -> 556292627000
A16: 17 | B16: JONAS DUARTE DA SILVA | C16: GOIANIA | D16: =+5562993380899 -> 5562993380899
A17: 24 | B17: BRENNO FELIPE GOMES DA SILVA | C17: GOIANIA | D17: =+556294700104 -> 556294700104
A18: 18 | B18: MARCIO JERONIMO ALVES | C18: GOIANIA | D18: =+5562995737803 -> 5562995737803
A19: 19 | B19: ROGERIO PEREIRA BARBOSA | C19: TRINDADE | D19: =+5562983295210 -> 5562983295210
A20: 126 | B20: GABRIEL TERRA ANDRADE PORTELLA | C20: GOIANIA | D20: =+5562981721490 -> 5562981721490
A21: 15 | B21: FRANCISCO JOSE DOS SANTOS LOURENÇO | C21: GOIANIA | D21: =+5562991779416 -> 5562991779416
A22: 36 | B22: NUBIA FLAVIA LEITE | C22: GOIANIA | D22: =+556291234123 -> 556291234123
A23: 23 | B23: FABIO CAMARGO DOS SANTOS | C23: GOIANIA | D23: =+556295045351 -> 556295045351
A24: 29 | B24: SIMONE DE JESUS PEREIRA | C24: CATALAO | D24: =+5564996929742 -> 5564996929742
A25: 55 | B25: THAYZA DE OLIVEIRA PEREIRA | C25: RIO VERDE | D25: =+556493070171 -> 556493070171
A26: 25 | B26: MATHEUS RIBEIRO SILVA | C26: ITUMBIARA | D26: =+556492682963 -> 556492682963
A27: 16 | B27: YAGO BORGES DE QUEIROZ | C27: ANAPOLIS | D27: =+5562994414211 -> 5562994414211
A28: 22 | B28: MARCELO AUGUSTO DE OLIVEIRA PEREIRA GOMES | D28: =+556292519929 -> 556292519929
A29: 26 | B29: RODRIGO MARQUES DE OLIVEIRA | C29: ANAPOLIS | D29: =+556291570770 -> 556291570770
A30: 21 | B30: CAMILA TRINDADE DE OLIVEIRA | C30: JATAI | D30: =+556492676362 -> 556492676362
A31: 28 | B31: LUCAS PEREIRA DE FARIA SILVA | C31: CALDAS NOVAS | D31: =+5564993432324 -> 5564993432324
B32: THALLYSON WILLIAM DE SOUSA SILVA | D32: =+556493275027 -> 556493275027
A33: 723 | B33: DANIEL ALEXANDRE DE ALMEIDA | C33: GOIÂNIA | D33: =+556292067536 -> 556292067536
A34: 60 | B34: KAYQUE DE JESUS OLIVEIRA | C34: GOIANIA | D34: =+556291327718 -> 556291327718
A35: 30 | B35: FERNANDA KELLY ALVES DA SILVA | C35: ARAGUAINA | D35: =+556391050813 -> 556391050813
A36: 31 | B36: KEVEN ALBERTO PAULINO DE SOUSA | C36: PALMAS | D36: =+556391178695 -> 556391178695
A37: 50 | B37: RAFAELA SILVA GOMES | C37: BARRA DO GARÇAS | D37: =+556692188888 -> 556692188888
A38: 34 | B38: JEFFERSON JUNIOR DE SOUZA | C38: PRIMAVERA DO LESTE | D38: =+556692270687 -> 556692270687
A39: 64 | B39: ERIK MATHEUS DE SOUZA MENDES | C39: SINOP | D39: =+556699008027 -> 556699008027
A40: 62 | B40: ROSILENE DA SILVA GONCALVES GAMBARRA | C40: CUIABA/VÁRZEA GRANDE | D40: =+556592377672 -> 556592377672
...

Sheet LOJAS
A1: REDE | B1: LOJA | C1: UF
A2: DIA A DIA | B2: DIA A DIA - LUÍS EDUARDO MAGALHÃES | C2: BA
A3: ATACADÃO | B3: ATACADÃO - ASA NORTE | C3: DF
A4: ATACADÃO | B4: ATACADÃO - BRASILIA | C4: DF
A5: ATACADÃO | B5: ATACADÃO - BRASÍLIA SIA | C5: DF
A6: ATACADÃO | B6: ATACADÃO - GAMA | C6: DF
A7: ATACADÃO | B7: ATACADÃO - PISTÃO SUL 343 | C7: DF
A8: ATACADÃO | B8: ATACADÃO - RECANTO DAS EMAS | C8: DF
A9: ATACADÃO | B9: ATACADÃO - SOBRADINHO | C9: DF
A10: ATACADÃO | B10: ATACADÃO - TAGUATINGA QNL | C10: DF
A11: BIG BOX | B11: BIG BOX - 211 NORTE | C11: DF
A12: BIG BOX | B12: BIG BOX - 402 NORTE | C12: DF
... A412: COSTA | B412: COSTA ATACADÃO - CENTRO DE GOIANIA | C412: GO

Sheet INDUSTRIA
A1: INDUSTRIA
A2: ALLEZA
A3: AUTENTICOCO
A4: AO QUADRADO
A5: COPRA
A6: CICOPAL GO
A7: CO LATICÍNIOS
A8: COOPATOS
A9: FRUTA POLPA
A10: GRUPO AMA
A11: DON LUIZ
A12: RB ALIMENTOS
... A27: CHULETÃO
